2025-07-22 02:46:20,977 DEBUG    root            Loaded Command Group: ['gcloud', 'projects']
2025-07-22 02:46:20,986 DEBUG    root            Loaded Command Group: ['gcloud', 'projects', 'create']
2025-07-22 02:46:20,989 DEBUG    root            Running [gcloud.projects.create] with arguments: [--set-as-default: "True", PROJECT_ID: "elparadisogonzalo-dev"]
2025-07-22 02:46:21,032 DEBUG    urllib3.connectionpool Starting new HTTPS connection (1): cloudresourcemanager.googleapis.com:443
2025-07-22 02:46:22,144 DEBUG    urllib3.connectionpool https://cloudresourcemanager.googleapis.com:443 "POST /v1/projects?alt=json HTTP/11" 409 None
2025-07-22 02:46:22,151 DEBUG    root            (gcloud.projects.create) Project creation failed. The project ID you specified is already in use by another project. Please try an alternative ID.
Traceback (most recent call last):
  File "/data/data/com.termux/files/home/google-cloud-sdk/lib/surface/projects/create.py", line 154, in Run
    create_op = projects_api.Create(
                ^^^^^^^^^^^^^^^^^^^^
  File "/data/data/com.termux/files/home/google-cloud-sdk/lib/googlecloudsdk/api_lib/cloudresourcemanager/projects_api.py", line 156, in Create
    return client.projects.Create(
           ^^^^^^^^^^^^^^^^^^^^^^^
  File "/data/data/com.termux/files/home/google-cloud-sdk/lib/googlecloudsdk/generated_clients/apis/cloudresourcemanager/v1/cloudresourcemanager_v1_client.py", line 706, in Create
    return self._RunMethod(
           ^^^^^^^^^^^^^^^^
  File "/data/data/com.termux/files/home/google-cloud-sdk/lib/third_party/apitools/base/py/base_api.py", line 747, in _RunMethod
    return self.ProcessHttpResponse(method_config, http_response, request)
           ^^^^^^^^^^^^^^^^^^^^^^^^^^^^^^^^^^^^^^^^^^^^^^^^^^^^^^^^^^^^^^^
  File "/data/data/com.termux/files/home/google-cloud-sdk/lib/third_party/apitools/base/py/base_api.py", line 753, in ProcessHttpResponse
    self.__ProcessHttpResponse(method_config, http_response, request))
    ^^^^^^^^^^^^^^^^^^^^^^^^^^^^^^^^^^^^^^^^^^^^^^^^^^^^^^^^^^^^^^^^^
  File "/data/data/com.termux/files/home/google-cloud-sdk/lib/third_party/apitools/base/py/base_api.py", line 612, in __ProcessHttpResponse
    raise exceptions.HttpError.FromResponse(
apitools.base.py.exceptions.HttpConflictError: HttpError accessing <https://cloudresourcemanager.googleapis.com/v1/projects?alt=json>: response: <{'vary': 'Origin, X-Origin, Referer', 'content-type': 'application/json; charset=UTF-8', 'content-encoding': 'gzip', 'date': 'Tue, 22 Jul 2025 01:46:22 GMT', 'server': 'ESF', 'x-xss-protection': '0', 'x-frame-options': 'SAMEORIGIN', 'x-content-type-options': 'nosniff', 'server-timing': 'gfet4t7; dur=145', 'alt-svc': 'h3=":443"; ma=2592000,h3-29=":443"; ma=2592000', 'transfer-encoding': 'chunked', 'status': 409}>, content <{
  "error": {
    "code": 409,
    "message": "Requested entity already exists",
    "status": "ALREADY_EXISTS"
  }
}
>

During handling of the above exception, another exception occurred:

Traceback (most recent call last):
  File "/data/data/com.termux/files/home/google-cloud-sdk/lib/googlecloudsdk/calliope/cli.py", line 985, in Execute
    resources = calliope_command.Run(cli=self, args=args)
                ^^^^^^^^^^^^^^^^^^^^^^^^^^^^^^^^^^^^^^^^^
  File "/data/data/com.termux/files/home/google-cloud-sdk/lib/googlecloudsdk/calliope/backend.py", line 945, in Run
    resources = command_instance.Run(args)
                ^^^^^^^^^^^^^^^^^^^^^^^^^^
  File "/data/data/com.termux/files/home/google-cloud-sdk/lib/surface/projects/create.py", line 165, in Run
    core_exceptions.reraise(exceptions.HttpException(msg))
  File "/data/data/com.termux/files/home/google-cloud-sdk/lib/googlecloudsdk/core/exceptions.py", line 149, in reraise
    six.reraise(type(exc_value), exc_value, tb)
  File "/data/data/com.termux/files/home/google-cloud-sdk/lib/third_party/six/__init__.py", line 718, in reraise
    raise value.with_traceback(tb)
  File "/data/data/com.termux/files/home/google-cloud-sdk/lib/surface/projects/create.py", line 154, in Run
    create_op = projects_api.Create(
                ^^^^^^^^^^^^^^^^^^^^
  File "/data/data/com.termux/files/home/google-cloud-sdk/lib/googlecloudsdk/api_lib/cloudresourcemanager/projects_api.py", line 156, in Create
    return client.projects.Create(
           ^^^^^^^^^^^^^^^^^^^^^^^
  File "/data/data/com.termux/files/home/google-cloud-sdk/lib/googlecloudsdk/generated_clients/apis/cloudresourcemanager/v1/cloudresourcemanager_v1_client.py", line 706, in Create
    return self._RunMethod(
           ^^^^^^^^^^^^^^^^
  File "/data/data/com.termux/files/home/google-cloud-sdk/lib/third_party/apitools/base/py/base_api.py", line 747, in _RunMethod
    return self.ProcessHttpResponse(method_config, http_response, request)
           ^^^^^^^^^^^^^^^^^^^^^^^^^^^^^^^^^^^^^^^^^^^^^^^^^^^^^^^^^^^^^^^
  File "/data/data/com.termux/files/home/google-cloud-sdk/lib/third_party/apitools/base/py/base_api.py", line 753, in ProcessHttpResponse
    self.__ProcessHttpResponse(method_config, http_response, request))
    ^^^^^^^^^^^^^^^^^^^^^^^^^^^^^^^^^^^^^^^^^^^^^^^^^^^^^^^^^^^^^^^^^
  File "/data/data/com.termux/files/home/google-cloud-sdk/lib/third_party/apitools/base/py/base_api.py", line 612, in __ProcessHttpResponse
    raise exceptions.HttpError.FromResponse(
googlecloudsdk.calliope.exceptions.HttpException: Project creation failed. The project ID you specified is already in use by another project. Please try an alternative ID.
2025-07-22 02:46:22,158 ERROR    root            (gcloud.projects.create) Project creation failed. The project ID you specified is already in use by another project. Please try an alternative ID.
2025-07-22 02:46:22,173 DEBUG    root            Metrics reporting process started...
